// Bug 384380 - False positive on a "Potential null pointer access" after a continue
// while & foreach loops
public void testBug384380_b() {
	if (this.complianceLevel >= ClassFileConstants.JDK1_5) {
		this.runConformTest(
			new String[] {
				"Test.java",
				"public class Test {\n" +
				"	public static class Container{\n" +
				"		public int property;\n" +
				"	}\n" +
				"	public static class CustomException extends Exception {\n" +
				"		private static final long	 serialVersionUID	= 1L;\n" +
				"	}\n" +
				"	public static void anotherMethod() throws CustomException {}\n" +
				"\n" +
				"	public static void method(final java.util.List<Container> list) {\n" +
				"		java.util.Iterator<Container> it = list.iterator();\n" +
				"		while (it.hasNext()) {\n" +
				"			final Container c = it.next();\n" +
				"			if(c == null)\n" +
				"				continue; // return or break, are fine though\n" +
				"\n" + 
				"			// without this try-catch+for+exception block it does not fails\n" +
				"			try {\n" +
				"				for(Container c1 : list) // needs a loop here (a 'while' or a 'for') to fail\n" +
				"					anotherMethod(); // throwing directly CustomException make it fails too\n" +
				"			} catch (final CustomException e) {\n" +
				"				// it fails even if catch is empty\n" +
				"			}\n" +
				"			c.property += 1; // \"Potential null pointer access: The variable c may be null at this location\"\n" +
				"		}\n" +
				"\n" +
				"	}\n" +
				"}\n"
			},
			"");
	}
}

