// Bug 359334 - Analysis for resource leak warnings does not consider exceptions as method exit points
// close() nested within finally provides protection for throw
public void test056throw3() {
	Map options = getCompilerOptions();
	options.put(JavaCore.COMPILER_PB_UNCLOSED_CLOSEABLE, CompilerOptions.ERROR);
	options.put(JavaCore.COMPILER_PB_POTENTIALLY_UNCLOSED_CLOSEABLE, CompilerOptions.ERROR);
	options.put(JavaCore.COMPILER_PB_EXPLICITLY_CLOSED_AUTOCLOSEABLE, CompilerOptions.ERROR);
	options.put(JavaCore.COMPILER_PB_DEAD_CODE, CompilerOptions.ERROR);
	this.runNegativeTest(
		new String[] {
			"X.java",
			"import java.io.FileReader;\n" +
			"public class X {\n" +
			"    void foo2x() throws Exception {\n" + 
			"        FileReader reader = new FileReader(\"file\"); // propose t-w-r\n" + 
			"        try {\n" + 
			"            reader.read();\n" + 
			"            throw new Exception(); // should not warn here\n" + 
			"        } catch (Exception e) {\n" + 
			"            throw new Exception();\n" + 
			"        } finally {\n" +
			"            if (reader != null)\n" +
			"                 try {\n" + 
			"                     reader.close();\n" +
			"                 } catch (java.io.IOException io) {}\n" + 
			"        }\n" + 
			"    }\n" + 
			"}\n"
		},
		"----------\n" + 
		"1. ERROR in X.java (at line 4)\n" + 
		"	FileReader reader = new FileReader(\"file\"); // propose t-w-r\n" + 
		"	           ^^^^^^\n" + 
		"Resource 'reader' should be managed by try-with-resource\n" + 
		"----------\n",
		null,
		true,
		options);	
}

